Workbook

Sheet Assumptions
C3: Select case | D3: 2
C4: Downside | D4: 1
C5: Base | D5: 2
C6: Upside | D6: 3
B8: Multiplier | C8: Assumptions | D8: 2021 | E8: =D8+1 -> 2022 | F8: =E8+1 -> 2023 | G8: =F8+1 -> 2024 | H8: =G8+1 -> 2025 | I8: =H8+1 -> 2026 | J8: =I8+1 -> 2027 | K8: =J8+1 -> 2028 | L8: =K8+1 -> 2029 | M8: =L8+1 -> 2030
C10: Revenue:
C11: Online store growth
C12: =OFFSET(C12,$D$3,0) -> Base | I12: =OFFSET(I12,$D$3,0) -> 0.075 | J12: =OFFSET(J12,$D$3,0) -> 0.0702 | K12: =OFFSET(K12,$D$3,0) -> 0.0696 | L12: =OFFSET(L12,$D$3,0) -> 0.0729 | M12: =OFFSET(M12,$D$3,0) -> 0.0716
B13: 0.5 | C13: Downside | I13: =I14*$B13 -> 0.0375 | J13: =J14*$B13 -> 0.0351 | K13: =K14*$B13 -> 0.0348 | L13: =L14*$B13 -> 0.03645 | M13: =M14*$B13 -> 0.0358 | N13: Macro slowdown + tariff drag on consumer discretionary. Retail growth was already single digits and Amazon themselves guided only 7-11% total revenue growth.
C14: Base | E14: ='FCF Components'!D8 -> -0.0093256783 | F14: ='FCF Components'!E8 -> 0.053944474 | G14: ='FCF Components'!F8 -> 0.065367962 | H14: ='FCF Components'!G8 -> 0.090102781 | I14: 0.075 | J14: 0.0702 | K14: 0.0696 | L14: 0.0729 | M14: 0.0716
B15: 1.35 | C15: Upside | I15: =I14*$B15 -> 0.10125 | J15: =J14*$B15 -> 0.09477 | K15: =K14*$B15 -> 0.09396 | L15: =L14*$B15 -> 0.098415 | M15: =M14*$B15 -> 0.09666 | N15: Same-day delivery expansion beyond 2,300 communities, AI-driven personalization lift, and market share gains from weaker competitors
C17: Physical stores growth
C18: =OFFSET(C18,$D$3,0) -> Base | I18: =OFFSET(I18,$D$3,0) -> 0.0507 | J18: =OFFSET(J18,$D$3,0) -> 0.05 | K18: =OFFSET(K18,$D$3,0) -> 0.0448 | L18: =OFFSET(L18,$D$3,0) -> 0.0432 | M18: =OFFSET(M18,$D$3,0) -> 0.0416
B19: 0.4 | C19: Downside | I19: =I20*$B19 -> 0.02028 | J19: =J20*$B19 -> 0.02 | K19: =K20*$B19 -> 0.01792 | L19: =L20*$B19 -> 0.01728 | M19: =M20*$B19 -> 0.01664 | N19: Whole Foods has seen limited expansion and Amazon Fresh closures signal strategic deprioritization.
C20: Base | E20: ='FCF Components'!D11 -> 0.11057101 | F20: ='FCF Components'!E11 -> 0.056267468 | G20: ='FCF Components'!F11 -> 0.059161258 | H20: ='FCF Components'!G11 -> 0.063445675 | I20: 0.0507 | J20: 0.05 | K20: 0.0448 | L20: 0.0432 | M20: 0.0416
B21: 1.4 | C21: Upside | I21: =I20*$B21 -> 0.07098 | J21: =J20*$B21 -> 0.07 | K21: =K20*$B21 -> 0.06272 | L21: =L20*$B21 -> 0.06048 | M21: =M20*$B21 -> 0.05824 | N21: Amazon One/Just Walk Out tech rollout + grocery automation. Note that physical retail isn't a strategic priority.
C23: Third-party seller services growth
C24: =OFFSET(C24,$D$3,0) -> Base | I24: =OFFSET(I24,$D$3,0) -> 0.1054 | J24: =OFFSET(J24,$D$3,0) -> 0.09 | K24: =OFFSET(K24,$D$3,0) -> 0.0954 | L24: =OFFSET(L24,$D$3,0) -> 0.0893 | M24: =OFFSET(M24,$D$3,0) -> 0.0833
B25: 0.65 | C25: Downside | I25: =I26*$B25 -> 0.06851 | J25: =J26*$B25 -> 0.0585 | K25: =K26*$B25 -> 0.06201 | L25: =L26*$B25 -> 0.058045 | M25: =M26*$B25 -> 0.054145 | N25: FTC Antitrust Trial could reduce margins
C26: Base | E26: ='FCF Components'!D14 -> 0.13882708 | F26: ='FCF Components'!E14 -> 0.1897533 | G26: ='FCF Components'!F14 -> 0.1149065 | H26: ='FCF Components'!G14 -> 0.10257067 | I26: 0.1054 | J26: 0.09 | K26: 0.0954 | L26: 0.0893 | M26: 0.0833
B27: 1.25 | C27: Upside | I27: =I26*$B27 -> 0.13175 | J27: =J26*$B27 -> 0.1125 | K27: =K26*$B27 -> 0.11925 | L27: =L26*$B27 -> 0.111625 | M27: =M26*$B27 -> 0.104125 | N27: Buy with Prime expansion off-Amazon, Multi-channel fulfillment opening to larger sellers (Walmart, Shopify)
C29: Advertising services growth
C30: =OFFSET(C30,$D$3,0) -> Base | I30: =OFFSET(I30,$D$3,0) -> 0.1845 | J30: =OFFSET(J30,$D$3,0) -> 0.1727 | K30: =OFFSET(K30,$D$3,0) -> 0.1519 | L30: =OFFSET(L30,$D$3,0) -> 0.1389 | M30: =OFFSET(M30,$D$3,0) -> 0.1303
B31: 0.7 | C31: Downside | I31: =I32*$B31 -> 0.12915 | J31: =J32*$B31 -> 0.12089 | K31: =K32*$B31 -> 0.10633 | L31: =L32*$B31 -> 0.09723 | M31: =M32*$B31 -> 0.09121 | N31: Consumer spending pullback or recession fears reduce ad growth.
C32: Base | E32: ='FCF Components'!D17 -> 0.21113607 | F32: ='FCF Components'!E17 -> 0.24290522 | G32: ='FCF Components'!F17 -> 0.19843943 | H32: ='FCF Components'!G17 -> 0.22095919 | I32: 0.1845 | J32: 0.1727 | K32: 0.1519 | L32: 0.1389 | M32: 0.1303
B33: 1.3 | C33: Upside | I33: =I32*$B33 -> 0.23985 | J33: =J32*$B33 -> 0.22451 | K33: =K32*$B33 -> 0.19747 | L33: =L32*$B33 -> 0.18057 | M33: =M32*$B33 -> 0.16939 | N33: Prime Video ad tiers grow, enhanced ad management across Prime Video, Twitch, Fire TV and third party sites/apps
C35: Subscription services growth
C36: =OFFSET(C36,$D$3,0) -> Base | I36: =OFFSET(I36,$D$3,0) -> 0.1034 | J36: =OFFSET(J36,$D$3,0) -> 0.0968 | K36: =OFFSET(K36,$D$3,0) -> 0.0898 | L36: =OFFSET(L36,$D$3,0) -> 0.0827 | M36: =OFFSET(M36,$D$3,0) -> 0.0792
B37: 0.7 | C37: Downside | I37: =I38*$B37 -> 0.07238 | J37: =J38*$B37 -> 0.06776 | K37: =K38*$B37 -> 0.06286 | L37: =L38*$B37 -> 0.05789 | M37: =M38*$B37 -> 0.05544 | N37: Prime subscriber growth slows down in developed markets
C38: Base | E38: ='FCF Components'!D20 -> 0.10859985 | F38: ='FCF Components'!E20 -> 0.1417173 | G38: ='FCF Components'!F20 -> 0.10358377 | H38: ='FCF Components'!G20 -> 0.11819985 | I38: 0.1034 | J38: 0.0968 | K38: 0.0898 | L38: 0.0827 | M38: 0.0792
B39: 1.3 | C39: Upside | I39: =I38*$B39 -> 0.13442 | J39: =J38*$B39 -> 0.12584 | K39: =K38*$B39 -> 0.11674 | L39: =L38*$B39 -> 0.10751 | M39: =M38*$B39 -> 0.10296 | N39: Prime keeps its competitive moat and expands into other segments like pharmacy, making attractive bundles
C41: AWS growth
C42: =OFFSET(C42,$D$3,0) -> Base | I42: =OFFSET(I42,$D$3,0) -> 0.2443 | J42: =OFFSET(J42,$D$3,0) -> 0.2289 | K42: =OFFSET(K42,$D$3,0) -> 0.2241 | L42: =OFFSET(L42,$D$3,0) -> 0.1869 | M42: =OFFSET(M42,$D$3,0) -> 0.1689
B43: 0.75 | C43: Downside | I43: =I44*$B43 -> 0.183225 | J43: =J44*$B43 -> 0.171675 | K43: =K44*$B43 -> 0.168075 | L43: =L44*$B43 -> 0.140175 | M43: =M44*$B43 -> 0.126675 | N43: Azure/GCP share increases, AI capex cycle peaks.
C44: Base | E44: ='FCF Components'!D23 -> 0.28767564 | F44: ='FCF Components'!E23 -> 0.13310278 | G44: ='FCF Components'!F23 -> 0.18509867 | H44: ='FCF Components'!G23 -> 0.1968184 | I44: 0.2443 | J44: 0.2289 | K44: 0.2241 | L44: 0.1869 | M44: 0.1689
B45: 1.15 | C45: Upside | I45: =I44*$B45 -> 0.280945 | J45: =J44*$B45 -> 0.263235 | K45: =K44*$B45 -> 0.257715 | L45: =L44*$B45 -> 0.214935 | M45: =M44*$B45 -> 0.194235 | N45: AI workload accelerates, Trainium adoption beyond Anthropic
C47: Other growth
C48: =OFFSET(C48,$D$3,0) -> Base | I48: =OFFSET(I48,$D$3,0) -> 0.04 | J48: =OFFSET(J48,$D$3,0) -> 0.04 | K48: =OFFSET(K48,$D$3,0) -> 0.04 | L48: =OFFSET(L48,$D$3,0) -> 0.04 | M48: =OFFSET(M48,$D$3,0) -> 0.04
B49: 0.9 | C49: Downside | I49: =I50*$B49 -> 0.036 | J49: =J50*$B49 -> 0.036 | K49: =K50*$B49 -> 0.036 | L49: =L50*$B49 -> 0.036 | M49: =M50*$B49 -> 0.036 | N49: Uncertainty around Kuiper, etc
C50: Base | E50: ='FCF Components'!D26 -> 0 | F50: ='FCF Components'!E26 -> 0.16741229 | G50: ='FCF Components'!F26 -> 0.094191206 | H50: ='FCF Components'!G26 -> 0.094009217 | I50: 0.04 | J50: 0.04 | K50: 0.04 | L50: 0.04 | M50: 0.04
...

Sheet FCF Components
L1: ="CURRENTLY VIEWING "&CHOOSE(Assumptions!$D$3,"DOWNSIDE","BASE","UPSIDE")&" CASE" -> CURRENTLY VIEWING BASE CASE
B2: Free Cash Flow Components | C2: Actual | H2: Expected
B3: USD ($) in millions | C3: 2021 | D3: =C3+1 -> 2022 | E3: =D3+1 -> 2023 | F3: =E3+1 -> 2024 | G3: =F3+1 -> 2025 | H3: =G3+1 -> 2026 | I3: =H3+1 -> 2027 | J3: =I3+1 -> 2028 | K3: =J3+1 -> 2029 | L3: =K3+1 -> 2030
B4: Income Statement:
B5: Revenues
B7: Online stores | C7: 222075 | D7: 220004 | E7: 231872 | F7: 247029 | G7: 269287 | H7: =G7*(1+Assumptions!I14) -> 289483.52 | I7: =H7*(1+Assumptions!J14) -> 309805.27 | J7: =I7*(1+Assumptions!K14) -> 331367.72 | K7: =J7*(1+Assumptions!L14) -> 355524.42 | L7: =K7*(1+Assumptions!M14) -> 380979.97
B8: Online stores growth | D8: =D7/C7-1 -> -0.0093256783 | E8: =E7/D7-1 -> 0.053944474 | F8: =F7/E7-1 -> 0.065367962 | G8: =G7/F7-1 -> 0.090102781 | H8: =Assumptions!I12 -> 0.075 | I8: =Assumptions!J12 -> 0.0702 | J8: =Assumptions!K12 -> 0.0696 | K8: =Assumptions!L12 -> 0.0729 | L8: =Assumptions!M12 -> 0.0716
B10: Physical stores | C10: 17075 | D10: 18963 | E10: 20030 | F10: 21215 | G10: 22561 | H10: =G10*(1+Assumptions!I20) -> 23704.843 | I10: =H10*(1+I11) -> 24890.085 | J10: =I10*(1+J11) -> 26005.161 | K10: =J10*(1+K11) -> 27128.584 | L10: =K10*(1+L11) -> 28257.133
B11: Physical stores growth | D11: =D10/C10-1 -> 0.11057101 | E11: =E10/D10-1 -> 0.056267468 | F11: =F10/E10-1 -> 0.059161258 | G11: =G10/F10-1 -> 0.063445675 | H11: =Assumptions!I18 -> 0.0507 | I11: =Assumptions!J18 -> 0.05 | J11: =Assumptions!K18 -> 0.0448 | K11: =Assumptions!L18 -> 0.0432 | L11: =Assumptions!M18 -> 0.0416
B13: Third-party seller services | C13: 103366 | D13: 117716 | E13: 140053 | F13: 156146 | G13: 172162 | H13: =G13*(1+Assumptions!I26) -> 190307.87 | I13: =H13*(1+I14) -> 207435.58 | J13: =I13*(1+J14) -> 227224.94 | K13: =J13*(1+K14) -> 247516.13 | L13: =K13*(1+L14) -> 268134.22
B14: Third-party seller services growth | D14: =D13/C13-1 -> 0.13882708 | E14: =E13/D13-1 -> 0.1897533 | F14: =F13/E13-1 -> 0.1149065 | G14: =G13/F13-1 -> 0.10257067 | H14: =Assumptions!I24 -> 0.1054 | I14: =Assumptions!J24 -> 0.09 | J14: =Assumptions!K24 -> 0.0954 | K14: =Assumptions!L24 -> 0.0893 | L14: =Assumptions!M24 -> 0.0833
B16: Advertising services | C16: 31160 | D16: 37739 | E16: 46906 | F16: 56214 | G16: 68635 | H16: =G16*(1+Assumptions!I32) -> 81298.157 | I16: =H16*(1+I17) -> 95338.349 | J16: =I16*(1+J17) -> 109820.24 | K16: =J16*(1+K17) -> 125074.28 | L16: =K16*(1+L17) -> 141371.45
B17: Advertising services growth | D17: =D16/C16-1 -> 0.21113607 | E17: =E16/D16-1 -> 0.24290522 | F17: =F16/E16-1 -> 0.19843943 | G17: =G16/F16-1 -> 0.22095919 | H17: =Assumptions!I30 -> 0.1845 | I17: =Assumptions!J30 -> 0.1727 | J17: =Assumptions!K30 -> 0.1519 | K17: =Assumptions!L30 -> 0.1389 | L17: =Assumptions!M30 -> 0.1303
B19: Subscription services | C19: 31768 | D19: 35218 | E19: 40209 | F19: 44374 | G19: 49619 | H19: =G19*(1+Assumptions!I38) -> 54749.605 | I19: =H19*(1+I20) -> 60049.366 | J19: =I19*(1+J20) -> 65441.799 | K19: =J19*(1+K20) -> 70853.836 | L19: =K19*(1+L20) -> 76465.46
B20: Subscription services growth | D20: =D19/C19-1 -> 0.10859985 | E20: =E19/D19-1 -> 0.1417173 | F20: =F19/E19-1 -> 0.10358377 | G20: =G19/F19-1 -> 0.11819985 | H20: =Assumptions!I36 -> 0.1034 | I20: =Assumptions!J36 -> 0.0968 | J20: =Assumptions!K36 -> 0.0898 | K20: =Assumptions!L36 -> 0.0827 | L20: =Assumptions!M36 -> 0.0792
B22: AWS | C22: 62202 | D22: 80096 | E22: 90757 | F22: 107556 | G22: 128725 | H22: =G22*(1+Assumptions!I38) -> 142035.16 | I22: =H22*(1+I23) -> 174547.01 | J22: =I22*(1+J23) -> 213663 | K22: =J22*(1+K23) -> 253596.61 | L22: =K22*(1+L23) -> 296429.08
B23: AWS growth | D23: =D22/C22-1 -> 0.28767564 | E23: =E22/D22-1 -> 0.13310278 | F23: =F22/E22-1 -> 0.18509867 | G23: =G22/F22-1 -> 0.1968184 | H23: =Assumptions!I42 -> 0.2443 | I23: =Assumptions!J42 -> 0.2289 | J23: =Assumptions!K42 -> 0.2241 | K23: =Assumptions!L42 -> 0.1869 | L23: =Assumptions!M42 -> 0.1689
B25: Other | C25: 2176 | D25: 4247 | E25: 4958 | F25: 5425 | G25: 5935 | H25: =G25*(1+Assumptions!I50) -> 6172.4 | I25: =H25*(1+I26) -> 6419.296 | J25: =I25*(1+J26) -> 6676.0678 | K25: =J25*(1+K26) -> 6943.1106 | L25: =K25*(1+L26) -> 7220.835
B26: Other growth | E26: =E25/D25-1 -> 0.16741229 | F26: =F25/E25-1 -> 0.094191206 | G26: =G25/F25-1 -> 0.094009217 | H26: =Assumptions!I48 -> 0.04 | I26: =Assumptions!J48 -> 0.04 | J26: =Assumptions!K48 -> 0.04 | K26: =Assumptions!L48 -> 0.04 | L26: =Assumptions!M48 -> 0.04
B28: Net sales | C28: =SUM(C25,C22,C19,C16,C13,C10,C7) -> 469822 | D28: =SUM(D25,D22,D19,D16,D13,D10,D7) -> 513983 | E28: =SUM(E25,E22,E19,E16,E13,E10,E7) -> 574785 | F28: =SUM(F25,F22,F19,F16,F13,F10,F7) -> 637959 | G28: =SUM(G25,G22,G19,G16,G13,G10,G7) -> 716924 | H28: =SUM(H25,H22,H19,H16,H13,H10,H7) -> 787751.57 | I28: =SUM(I25,I22,I19,I16,I13,I10,I7) -> 878484.96 | J28: =SUM(J25,J22,J19,J16,J13,J10,J7) -> 980198.93 | ... L28: =SUM(L25,L22,L19,L16,L13,L10,L7) -> 1198858.2
B29: change ($) | D29: =D28-C28 -> 44161 | E29: =E28-D28 -> 60802 | F29: =F28-E28 -> 63174 | G29: =G28-F28 -> 78965 | H29: =H28-G28 -> 70827.57 | I29: =I28-H28 -> 90733.393 | J29: =J28-I28 -> 101713.96 | K29: =K28-J28 -> 106438.04 | L29: =L28-K28 -> 112221.19
B31: Cost of sales | C31: 272344 | D31: 288831 | E31: 304739 | F31: 326288 | G31: 356414 | H31: =H32*H28 -> 386786.02 | I31: =I32*I28 -> 421233.54 | J31: =J32*J28 -> 452361.8 | K31: =K32*K28 -> 497897.06 | L31: =L32*L28 -> 536848.68
B32: % of revenue | C32: =C31/C28 -> 0.57967486 | D32: =D31/D28 -> 0.5619466 | E32: =E31/E28 -> 0.53017911 | F32: =F31/F28 -> 0.51145607 | G32: =G31/G28 -> 0.49714335 | H32: =Assumptions!I84 -> 0.491 | I32: =Assumptions!J84 -> 0.4795 | J32: =Assumptions!K84 -> 0.4615 | K32: =Assumptions!L84 -> 0.4582 | L32: =Assumptions!M84 -> 0.4478
B34: Gross profit | C34: =C28-C31 -> 197478 | D34: =D28-D31 -> 225152 | E34: =E28-E31 -> 270046 | F34: =F28-F31 -> 311671 | G34: =G28-G31 -> 360510 | H34: =H28-H31 -> 400965.55 | I34: =I28-I31 -> 457251.42 | J34: =J28-J31 -> 527837.12 | ... L34: =L28-L31 -> 662009.47
B36: Operating expenses
B37: Fulfillment | C37: 75111 | D37: 84299 | E37: 90619 | F37: 98505 | G37: 109074 | H37: =H28*Assumptions!I54 -> 119808.88 | I37: =I28*Assumptions!J54 -> 131286.6 | J37: =J28*Assumptions!K54 -> 143537.14 | K37: =K28*Assumptions!L54 -> 154144.61 | L37: =L28*Assumptions!M54 -> 165031.06
B38: Technology and infrastructure | C38: 56052 | D38: 73213 | E38: 85622 | F38: 88544 | G38: 108521 | H38: =H28*Assumptions!I60 -> 123755.77 | I38: =I28*Assumptions!J60 -> 140381.9 | J38: =J28*Assumptions!K60 -> 163007.08 | K38: =K28*Assumptions!L60 -> 184510.96 | L38: =L28*Assumptions!M60 -> 204525.2
B39: Sales and marketing | C39: 32551 | D39: 42238 | E39: 44370 | F39: 43907 | G39: 47129 | H39: =H28*Assumptions!I66 -> 51282.627 | I39: =I28*Assumptions!J66 -> 56662.28 | J39: =J28*Assumptions!K66 -> 61458.473 | K39: =K28*Assumptions!L66 -> 65958.864 | L39: =L28*Assumptions!M66 -> 70972.403
B40: General and administrative | C40: 8823 | D40: 11891 | E40: 11816 | F40: 11359 | G40: 11172 | H40: =H28*Assumptions!I72 -> 12288.924 | I40: =I28*Assumptions!J72 -> 14055.759 | J40: =J28*Assumptions!K72 -> 14506.944 | K40: =K28*Assumptions!L72 -> 14995.59 | L40: =L28*Assumptions!M72 -> 15705.042
B41: Other expenses | C41: 62 | D41: 1263 | E41: 767 | F41: 763 | G41: 4639 | H41: =H28*Assumptions!I78 -> 1508.14 | I41: =I28*Assumptions!J78 -> 1636.42 | J41: =J28*Assumptions!K78 -> 1965.34 | K41: =K28*Assumptions!L78 -> 2209.81 | L41: =L28*Assumptions!M78 -> 2397.7163
B43: Total operating expenses | C43: =SUM(C37:C41) -> 172599 | D43: =SUM(D37:D41) -> 212904 | E43: =SUM(E37:E41) -> 233194 | F43: =SUM(F37:F41) -> 243078 | G43: =SUM(G37:G41) -> 280535 | H43: =SUM(H37:H41) -> 308644.34 | I43: =SUM(I37:I41) -> 344022.96 | J43: =SUM(J37:J41) -> 384474.98 | ... L43: =SUM(L37:L41) -> 458631.42
B45: EBIT | C45: =C34-C43 -> 24879 | D45: =D34-D43 -> 12248 | E45: =E34-E43 -> 36852 | F45: =F34-F43 -> 68593 | G45: =G34-G43 -> 79975 | H45: =H34-H43 -> 92321.206 | I45: =I34-I43 -> 113228.47 | J45: =J34-J43 -> 143362.14 | ... L45: =L34-L43 -> 203378.05
B47: Interest income | C47: 448 | D47: 989 | E47: 2949 | F47: 4677 | G47: 4381
B48: Interest expense | C48: 1809 | D48: 2367 | E48: 3182 | F48: 2406 | G48: 2274
B49: Other income | C49: =14651-19 -> 14632 | D49: =-16266-540 -> -16806 | E49: =1115-177 -> 938 | F49: =-1829-421 -> -2250 | G49: =15320-91 -> 15229
B51: EBT | C51: =C45+C47-C48+C49 -> 38150 | D51: =D45+D47-D48+D49 -> -5936 | E51: =E45+E47-E48+E49 -> 37557 | F51: =F45+F47-F48+F49 -> 68614 | G51: =G45+G47-G48+G49 -> 97311 | H51: =H45+H47-H48+H49 -> 92321.206 | I51: =I45+I47-I48+I49 -> 113228.47 | J51: =J45+J47-J48+J49 -> 143362.14 | ... L51: =L45+L47-L48+L49 -> 203378.05
B52: Taxes | C52: 4791 | D52: -3217 | E52: 7120 | F52: 9265 | G52: 19087 | H52: =H51*Assumptions!$D$132 -> 14917.648 | I52: =I51*Assumptions!$D$132 -> 18295.931 | J52: =J51*Assumptions!$D$132 -> 23165.057 | K52: =K51*Assumptions!$D$132 -> 26971.647 | L52: =L51*Assumptions!$D$132 -> 32862.68
B54: Net income | C54: =C51-C52 -> 33359 | D54: =D51-D52 -> -2719 | E54: =E51-E52 -> 30437 | F54: =F51-F52 -> 59349 | G54: =G51-G52 -> 78224 | H54: =H51-H52 -> 77403.557 | I54: =I51-I52 -> 94932.535 | J54: =J51-J52 -> 120197.09 | ... L54: =L51-L52 -> 170515.37
B56: Capital Expenditures and Depreciation:
B58: Gross property and equipment | C58: 238800 | D58: 283730 | E58: 324288 | F58: 394055 | G58: 534098 | H58: =G58+G62 -> 662418 | I58: =H58+H62 -> 851478.38 | J58: =I58+I62 -> 1027175.4 | K58: =J58+J62 -> 1203611.2 | L58: =K58+K62 -> 1366606.7 | M58: =_xlfn.FORMULATEXT(L58) -> =K58+K62
...

Sheet FCF Calculation
G2: ="CURRENTLY VIEWING "&CHOOSE(Assumptions!$D$3,"DOWNSIDE","BASE","UPSIDE")&" CASE" -> CURRENTLY VIEWING BASE CASE
B3: Free Cash Flow Calculation | C3: Expected
B4: USD ($) in millions | C4: 2026 | D4: =C4+1 -> 2027 | E4: =D4+1 -> 2028 | F4: =E4+1 -> 2029 | G4: =F4+1 -> 2030
B6: EBIT | C6: ='FCF Components'!H45 -> 92321.206 | D6: ='FCF Components'!I45 -> 113228.47 | E6: ='FCF Components'!J45 -> 143362.14 | F6: ='FCF Components'!K45 -> 166920.08 | G6: ='FCF Components'!L45 -> 203378.05
B7: (1-Tax Rate) | C7: ='WACC Calculation'!$K$9 -> 0.8384158 | D7: ='WACC Calculation'!$K$9 -> 0.8384158 | E7: ='WACC Calculation'!$K$9 -> 0.8384158 | F7: ='WACC Calculation'!$K$9 -> 0.8384158 | G7: ='WACC Calculation'!$K$9 -> 0.8384158
B8: EBIT(1-Tax Rate) | C8: =C6*C7 -> 77403.557 | D8: =D6*D7 -> 94932.535 | E8: =E6*E7 -> 120197.09 | F8: =F6*F7 -> 139948.43 | G8: =G6*G7 -> 170515.37
B9: Depreciation | C9: ='FCF Components'!H63 -> 90360.455 | D9: ='FCF Components'!I63 -> 112070.05 | E9: ='FCF Components'!J63 -> 144055.91 | F9: ='FCF Components'!K63 -> 173780.91 | G9: ='FCF Components'!L63 -> 203630.9
B10: Capital Expenditures | C10: ='FCF Components'!H62 -> 189060.38 | D10: ='FCF Components'!I62 -> 175696.99 | E10: ='FCF Components'!J62 -> 176435.81 | F10: ='FCF Components'!K62 -> 162995.55 | G10: ='FCF Components'!L62 -> 179828.72
B11: Change in NWC | C11: ='FCF Components'!H93 -> 4366.0939 | D11: ='FCF Components'!I93 -> -3039.4212 | E11: ='FCF Components'!J93 -> 5696.4822 | F11: ='FCF Components'!K93 -> -11707.674 | G11: ='FCF Components'!L93 -> -2182.133
B12: Free Cash Flow | C12: =C8+C9-C10-C11 -> -25662.458 | D12: =D8+D9-D10-D11 -> 34345.019 | E12: =E8+E9-E10-E11 -> 82120.708 | F12: =F8+F9-F10-F11 -> 162441.46 | G12: =G8+G9-G10-G11 -> 196499.68

Sheet WACC Calculation
B3: WACC Calculation | D3: Cost of Equity (CAPM) | G3: Cost of debt | J3: WACC
D4: Risk-free rate | E4: 0.04229 | G4: Interest expense | H4: ='FCF Components'!G48 -> 2274 | J4: Cost of equity | K4: =E7 -> 0.103838
D5: Equity beta | E5: 1.38 | G5: Debt | H5: 65648 | J5: Weight of equity | K5: =F12 -> 0.86229031
D6: Expected market return | E6: =E4+4.46% -> 0.08689 | G6: Cost of debt | H6: =H4/H5 -> 0.034639288
D7: Cost of equity | E7: =E5*(E6-E4)+E4 -> 0.103838 | J7: Cost of debt | K7: 0.06
J8: Weight of debt | K8: =F13 -> 0.13770969
J9: (1-Tax Rate) | K9: =1-Assumptions!D132 -> 0.8384158
D11: Weight of Debt and Equity | E11: Total | F11: Weight | J11: WACC | K11: =K4*K5+K7*K8*K9 -> 0.09646598
D12: Total Equity | E12: 411065 | F12: =E12/(E12+E13) -> 0.86229031
D13: Total Long Term Debt(Debt) | E13: =H5 -> 65648 | F13: =1-F12 -> 0.13770969

Sheet DCF
G2: ="CURRENTLY VIEWING "&CHOOSE(Assumptions!$D$3,"DOWNSIDE","BASE","UPSIDE")&" CASE" -> CURRENTLY VIEWING BASE CASE
B3: DCF | C3: 2026 | D3: =C3+1 -> 2027 | E3: =D3+1 -> 2028 | F3: =E3+1 -> 2029 | G3: =F3+1 -> 2030 | I3: Terminal Assumptions
B4: FCF | C4: ='FCF Calculation'!C12 -> -25662.458 | D4: ='FCF Calculation'!D12 -> 34345.019 | E4: ='FCF Calculation'!E12 -> 82120.708 | F4: ='FCF Calculation'!F12 -> 162441.46 | G4: ='FCF Calculation'!G12 -> 196499.68 | I4: Valuation Date | J4: =TODAY() -> 46129
B5: Discount Factor | C5: =(1/(1+($J$7))) -> 0.912021 | D5: =(C5/(1+$J$7)) -> 0.83178231 | E5: =(D5/(1+$J$7)) -> 0.75860293 | F5: =(E5/(1+$J$7)) -> 0.6918618 | G5: =(F5/(1+$J$7)) -> 0.63099249 | I5: Fiscal Year End | J5: 46387
B6: Present Value | C6: =C4*C5 -> -23404.701 | D6: =D4*D5 -> 28567.579 | E6: =E4*E5 -> 62297.01 | F6: =F4*F5 -> 112387.04 | G6: =G4*G5 -> 123989.82
I7: WACC | J7: ='WACC Calculation'!K11 -> 0.09646598
I8: Terminal Growth Rate | J8: 0.03
C9: Growth Rate YoY
B10: WACC | C10: =D10-0.005 -> 0.02 | D10: =E10-0.005 -> 0.025 | E10: =J8 -> 0.03 | F10: =E10+0.005 -> 0.035 | G10: =F10+0.005 -> 0.04 | I10: Current Valuation
B11: =B12-0.01 -> 0.07646598 | C11: =(($C$4*1/(1+$B11)+$D$4*1/(1+$B11)^2+$E$4*1/(1+$B11)^3+$F$4*1/(1+$B11)^4+$G$4*1/(1+$B11)^5+(($G$4*(1+C$10))/($B11-C$10))*1/(1+$B11)^5)-$J$15+$J$16)/$J$18 -> 261.33451 | D11: =(($C$4*1/(1+$B11)+$D$4*1/(1+$B11)^2+$E$4*1/(1+$B11)^3+$F$4*1/(1+$B11)^4+$G$4*1/(1+$B11)^5+(($G$4*(1+D$10))/($B11-D$10))*1/(1+$B11)^5)-$J$15+$J$16)/$J$18 -> 284.78893 | E11: =(($C$4*1/(1+$B11)+$D$4*1/(1+$B11)^2+$E$4*1/(1+$B11)^3+$F$4*1/(1+$B11)^4+$G$4*1/(1+$B11)^5+(($G$4*(1+E$10))/($B11-E$10))*1/(1+$B11)^5)-$J$15+$J$16)/$J$18 -> 313.291 | F11: =(($C$4*1/(1+$B11)+$D$4*1/(1+$B11)^2+$E$4*1/(1+$B11)^3+$F$4*1/(1+$B11)^4+$G$4*1/(1+$B11)^5+(($G$4*(1+F$10))/($B11-F$10))*1/(1+$B11)^5)-$J$15+$J$16)/$J$18 -> 348.66668 | G11: =(($C$4*1/(1+$B11)+$D$4*1/(1+$B11)^2+$E$4*1/(1+$B11)^3+$F$4*1/(1+$B11)^4+$G$4*1/(1+$B11)^5+(($G$4*(1+G$10))/($B11-G$10))*1/(1+$B11)^5)-$J$15+$J$16)/$J$18 -> 393.74336 | I11: Terminal Value | J11: =(G4*(1+J8))/(J7-J8) -> 3045086.6
B12: =B13-0.01 -> 0.08646598 | C12: =(($C$4*1/(1+$B12)+$D$4*1/(1+$B12)^2+$E$4*1/(1+$B12)^3+$F$4*1/(1+$B12)^4+$G$4*1/(1+$B12)^5+(($G$4*(1+C$10))/($B12-C$10))*1/(1+$B12)^5)-$J$15+$J$16)/$J$18 -> 216.95747 | D12: =(($C$4*1/(1+$B12)+$D$4*1/(1+$B12)^2+$E$4*1/(1+$B12)^3+$F$4*1/(1+$B12)^4+$G$4*1/(1+$B12)^5+(($G$4*(1+D$10))/($B12-D$10))*1/(1+$B12)^5)-$J$15+$J$16)/$J$18 -> 233.03555 | E12: =(($C$4*1/(1+$B12)+$D$4*1/(1+$B12)^2+$E$4*1/(1+$B12)^3+$F$4*1/(1+$B12)^4+$G$4*1/(1+$B12)^5+(($G$4*(1+E$10))/($B12-E$10))*1/(1+$B12)^5)-$J$15+$J$16)/$J$18 -> 251.96103 | F12: =(($C$4*1/(1+$B12)+$D$4*1/(1+$B12)^2+$E$4*1/(1+$B12)^3+$F$4*1/(1+$B12)^4+$G$4*1/(1+$B12)^5+(($G$4*(1+F$10))/($B12-F$10))*1/(1+$B12)^5)-$J$15+$J$16)/$J$18 -> 274.56378 | G12: =(($C$4*1/(1+$B12)+$D$4*1/(1+$B12)^2+$E$4*1/(1+$B12)^3+$F$4*1/(1+$B12)^4+$G$4*1/(1+$B12)^5+(($G$4*(1+G$10))/($B12-G$10))*1/(1+$B12)^5)-$J$15+$J$16)/$J$18 -> 302.03091 | I12: PV of Terminal Value | J12: =J11*G5 -> 1921426.8
B13: =J7 -> 0.09646598 | C13: =(($C$4*1/(1+$B13)+$D$4*1/(1+$B13)^2+$E$4*1/(1+$B13)^3+$F$4*1/(1+$B13)^4+$G$4*1/(1+$B13)^5+(($G$4*(1+C$10))/($B13-C$10))*1/(1+$B13)^5)-$J$15+$J$16)/$J$18 -> 184.34528 | D13: =(($C$4*1/(1+$B13)+$D$4*1/(1+$B13)^2+$E$4*1/(1+$B13)^3+$F$4*1/(1+$B13)^4+$G$4*1/(1+$B13)^5+(($G$4*(1+D$10))/($B13-D$10))*1/(1+$B13)^5)-$J$15+$J$16)/$J$18 -> 195.93265 | E13: =(($C$4*1/(1+$B13)+$D$4*1/(1+$B13)^2+$E$4*1/(1+$B13)^3+$F$4*1/(1+$B13)^4+$G$4*1/(1+$B13)^5+(($G$4*(1+E$10))/($B13-E$10))*1/(1+$B13)^5)-$J$15+$J$16)/$J$18 -> 209.26337 | F13: =(($C$4*1/(1+$B13)+$D$4*1/(1+$B13)^2+$E$4*1/(1+$B13)^3+$F$4*1/(1+$B13)^4+$G$4*1/(1+$B13)^5+(($G$4*(1+F$10))/($B13-F$10))*1/(1+$B13)^5)-$J$15+$J$16)/$J$18 -> 224.76289 | G13: =(($C$4*1/(1+$B13)+$D$4*1/(1+$B13)^2+$E$4*1/(1+$B13)^3+$F$4*1/(1+$B13)^4+$G$4*1/(1+$B13)^5+(($G$4*(1+G$10))/($B13-G$10))*1/(1+$B13)^5)-$J$15+$J$16)/$J$18 -> 243.00734 | I13: PV of Present Value | J13: =SUM(C6:G6) -> 303836.75
B14: =B13+0.01 -> 0.10646598 | C14: =(($C$4*1/(1+$B14)+$D$4*1/(1+$B14)^2+$E$4*1/(1+$B14)^3+$F$4*1/(1+$B14)^4+$G$4*1/(1+$B14)^5+(($G$4*(1+C$10))/($B14-C$10))*1/(1+$B14)^5)-$J$15+$J$16)/$J$18 -> 159.40982 | D14: =(($C$4*1/(1+$B14)+$D$4*1/(1+$B14)^2+$E$4*1/(1+$B14)^3+$F$4*1/(1+$B14)^4+$G$4*1/(1+$B14)^5+(($G$4*(1+D$10))/($B14-D$10))*1/(1+$B14)^5)-$J$15+$J$16)/$J$18 -> 168.07863 | E14: =(($C$4*1/(1+$B14)+$D$4*1/(1+$B14)^2+$E$4*1/(1+$B14)^3+$F$4*1/(1+$B14)^4+$G$4*1/(1+$B14)^5+(($G$4*(1+E$10))/($B14-E$10))*1/(1+$B14)^5)-$J$15+$J$16)/$J$18 -> 177.88111 | F14: =(($C$4*1/(1+$B14)+$D$4*1/(1+$B14)^2+$E$4*1/(1+$B14)^3+$F$4*1/(1+$B14)^4+$G$4*1/(1+$B14)^5+(($G$4*(1+F$10))/($B14-F$10))*1/(1+$B14)^5)-$J$15+$J$16)/$J$18 -> 189.05523 | G14: =(($C$4*1/(1+$B14)+$D$4*1/(1+$B14)^2+$E$4*1/(1+$B14)^3+$F$4*1/(1+$B14)^4+$G$4*1/(1+$B14)^5+(($G$4*(1+G$10))/($B14-G$10))*1/(1+$B14)^5)-$J$15+$J$16)/$J$18 -> 201.91052 | I14: PV of EV | J14: =J13+J12 -> 2225263.6
B15: =B14+0.01 -> 0.11646598 | C15: =(($C$4*1/(1+$B15)+$D$4*1/(1+$B15)^2+$E$4*1/(1+$B15)^3+$F$4*1/(1+$B15)^4+$G$4*1/(1+$B15)^5+(($G$4*(1+C$10))/($B15-C$10))*1/(1+$B15)^5)-$J$15+$J$16)/$J$18 -> 139.75841 | D15: =(($C$4*1/(1+$B15)+$D$4*1/(1+$B15)^2+$E$4*1/(1+$B15)^3+$F$4*1/(1+$B15)^4+$G$4*1/(1+$B15)^5+(($G$4*(1+D$10))/($B15-D$10))*1/(1+$B15)^5)-$J$15+$J$16)/$J$18 -> 146.43443 | E15: =(($C$4*1/(1+$B15)+$D$4*1/(1+$B15)^2+$E$4*1/(1+$B15)^3+$F$4*1/(1+$B15)^4+$G$4*1/(1+$B15)^5+(($G$4*(1+E$10))/($B15-E$10))*1/(1+$B15)^5)-$J$15+$J$16)/$J$18 -> 153.88254 | F15: =(($C$4*1/(1+$B15)+$D$4*1/(1+$B15)^2+$E$4*1/(1+$B15)^3+$F$4*1/(1+$B15)^4+$G$4*1/(1+$B15)^5+(($G$4*(1+F$10))/($B15-F$10))*1/(1+$B15)^5)-$J$15+$J$16)/$J$18 -> 162.24491 | G15: =(($C$4*1/(1+$B15)+$D$4*1/(1+$B15)^2+$E$4*1/(1+$B15)^3+$F$4*1/(1+$B15)^4+$G$4*1/(1+$B15)^5+(($G$4*(1+G$10))/($B15-G$10))*1/(1+$B15)^5)-$J$15+$J$16)/$J$18 -> 171.70089 | I15: - Debt | J15: ='WACC Calculation'!H5 -> 65648
I16: + Cash | J16: 86810
I17: PV of Equity | J17: =J14-J15+J16 -> 2246425.6
I18: Shares | J18: 10734.92
I19: Price per share | J19: =J17/J18 -> 209.26337
F23: Case Probabilities | I23: Base | J23: 209.26337
F24: Downside | G24: 0.1 | I24: Upside | J24: 264.96069
F25: Base | G25: 0.6 | I25: Downside | J25: 159.17312
F26: Upside | G26: 0.3 | I26: Weighted Avg. | J26: =(J23*DCF!$G$25)+(J24*DCF!$G$26)+(J25*DCF!$G$24) -> 220.96354

Sheet Comps
A1: ($ in billions)
A2: Company | C2: Price | D2: Shares Outstanding | E2: Total Debt | F2: Total Cash | G2: Enterprise Value | J2: EV-based multiples
A3: Apple(AAPL) | C3: =C39 -> 248.8 | D3: 14.78 | E3: 90.51 | F3: 45.32 | G3: =C3*D3+E3-F3 -> 3722.454 | J3: Multiple | K3: Amazon Metric | L3: Avg. comp multiple | M3: Implied EV ($B) | N3: Equity Value ($B) | O3: Implied Price/Share
A4: Alphabet(GOOGL) | C4: =C40 -> 274.34 | D4: 12.07 | E4: 59.29 | F4: 30.71 | G4: =C4*D4+E4-F4 -> 3339.8638 | J4: EV/Sales | K4: ='FCF Components'!G28/1000 -> 716.924 | L4: =G18 -> 5.7256333 | M4: =L4*K4 -> 4104.8439 | N4: =M4-$L$12+$L$13 -> 4126.0059 | O4: =N4/$L$15 -> 385.96875
A5: Meta(META) | C5: =C41 -> 525.72 | D5: 2.53 | E5: 83.9 | F5: 35.87 | G5: =C5*D5+E5-F5 -> 1378.1016 | J5: EV/EBITDA | K5: ='FCF Components'!G45/1000 + ('FCF Components'!G63/1000) -> 145.731 | L5: =G27 -> 16.466421 | M5: =L5*K5 -> 2399.668 | N5: =M5-$L$12+$L$13 -> 2420.83 | O5: =N5/$L$15 -> 226.45744
A6: Microsoft(MSFT) | C6: =C42 -> 356.77 | D6: 7.43 | E6: 57.61 | F6: 24.3 | G6: =C6*D6+E6-F6 -> 2684.1111 | J6: EV/FCF* | K6: 24.2 | L6: =G36 -> 23.908474 | M6: =L6*K6 -> 578.58508 | N6: =M6-$L$12+$L$13 -> 599.74708 | O6: =N6/$L$15 -> 56.103562
A7: Walmart(WMT) | C7: =C43 -> 122.89 | D7: 7.97 | E7: 67.1 | F7: 10.73 | G7: =C7*D7+E7-F7 -> 1035.8033
A8: Alibaba(BABA) | C8: =C44 -> 122.69 | D8: 2.39 | E8: 262.74 | F8: 128.17 | G8: =C8*D8+E8-F8 -> 427.7991 | H8: (CNY) | J8: Price-based multiple
J9: Multiple | K9: Amazon Metric | L9: Avg. comp multiple | M9: Implied EV ($B) | N9: Implied Price/Share
J10: P/E | K10: ='FCF Components'!G54/1000/L15 -> 7.317493 | L10: =G45 -> 24.77388 | M10: =L10*K10 -> 181.2827 | N10: =L10*K10 -> 181.2827
A11: Company | C11: Enterprise Value | E11: Sales | G11: EV/ Sales | J11: Average EV of all comps | L11: =AVERAGE(M4:M6) -> 2361.0324
A12: Apple(AAPL) | C12: =G3 -> 3722.454 | E12: 435.62 | G12: =C12/E12 -> 8.5451862 | J12: Debt | L12: ='WACC Calculation'!H5/1000 -> 65.648
A13: Alphabet(GOOGL) | C13: =G4 -> 3339.8638 | E13: 402.84 | G13: =C13/E13 -> 8.2907949 | J13: Cash | L13: 86.81
A14: Meta(META) | C14: =G5 -> 1378.1016 | E14: 200.97 | G14: =C14/E14 -> 6.8572503 | J14: Equity Value | L14: =L11-L12+L13 -> 2382.1944
A15: Microsoft(MSFT) | C15: =G6 -> 2684.1111 | E15: 305.45 | G15: =C15/E15 -> 8.7873992 | J15: Shares Outstanding | L15: =10.69 -> 10.69
A16: Walmart(WMT) | C16: =G7 -> 1035.8033 | E16: 713.16 | G16: =C16/E16 -> 1.4524136 | J16: Price per Share (EV Multiples) | L16: =L14/L15 -> 222.84325
A17: Alibaba(BABA) | C17: =G8 -> 427.7991 | E17: 1016.74 | G17: =C17/E17 -> 0.42075565 | H17: (CNY) | J17: Weighted Average | L17: =L16*0.75+N10*0.25 -> 212.45311
A18: Average EV/Sales | G18: =AVERAGE(G12:G17) -> 5.7256333
A20: Company | C20: Enterprise Value | E20: EBITDA | G20: EV/ EBITDA
A21: Apple(AAPL) | C21: =G3 -> 3722.454 | E21: 152.98 | G21: =C21/E21 -> 24.332945
A22: Alphabet(GOOGL) | C22: =G4 -> 3339.8638 | E22: 176.36 | G22: =C22/E22 -> 18.937763
A23: Meta(META) | C23: =G5 -> 1378.1016 | E23: 103.59 | G23: =C23/E23 -> 13.303423
A24: Microsoft(MSFT) | C24: =G6 -> 2684.1111 | E24: 183.29 | G24: =C24/E24 -> 14.644067
A25: Walmart(WMT) | C25: =G7 -> 1035.8033 | E25: 46.1 | G25: =C25/E25 -> 22.468618
A26: Alibaba(BABA) | C26: =G8 -> 427.7991 | E26: 83.69 | G26: =C26/E26 -> 5.1117111 | H26: (CNY)
A27: Average EV/EBITDA | G27: =AVERAGE(G21:G26) -> 16.466421
A29: Company | C29: Enterprise Value | E29: FCF | G29: EV/ FCF
A30: Apple(AAPL) | C30: =G3 -> 3722.454 | E30: 132.02 | G30: =C30/E30 -> 28.196137
A31: Alphabet(GOOGL) | C31: =G4 -> 3339.8638 | E31: 72.65 | G31: =C31/E31 -> 45.971972
A32: Meta(META) | C32: =G5 -> 1378.1016 | E32: 46.99 | G32: =C32/E32 -> 29.327551
A33: Microsoft(MSFT) | C33: =G6 -> 2684.1111 | E33: 81.92 | G33: =C33/E33 -> 32.765028
A34: Walmart(WMT) | C34: =G7 -> 1035.8033 | E34: 390.2 | G34: =C34/E34 -> 2.6545446
A35: Alibaba(BABA) | C35: =G8 -> 427.7991 | E35: 94.32 | G35: =C35/E35 -> 4.5356139 | H35: (CNY)
A36: Average EV/CF | G36: =AVERAGE(G30:G35) -> 23.908474
A38: Company | C38: Price | E38: EPS | G38: P/E
A39: Apple(AAPL) | C39: 248.8 | E39: 7.92 | G39: =C39/E39 -> 31.414141
A40: Alphabet(GOOGL) | C40: 274.34 | E40: 10.91 | G40: =C40/E40 -> 25.145738
A41: Meta(META) | C41: 525.72 | E41: 23.98 | G41: =C41/E41 -> 21.923269
A42: Microsoft(MSFT) | C42: 356.77 | E42: 16.04 | G42: =C42/E42 -> 22.242519
A43: Walmart(WMT) | C43: 122.89 | E43: 2.74 | G43: =C43/E43 -> 44.850365
...
